I'm sorry, but an uncaught exception occurred.

While running game code:
  File "game/mainTrail.rpy", line 3, in script
    if talked_to_angels == true:
  File "game/mainTrail.rpy", line 3, in <module>
    if talked_to_angels == true:
NameError: name 'true' is not defined

-- Full Traceback ------------------------------------------------------------

Full traceback:
  File "game/mainTrail.rpy", line 3, in script
    if talked_to_angels == true:
  File "/Applications/renpy-8.3.4-sdk/renpy/ast.py", line 1849, in execute
    if renpy.python.py_eval(condition):
  File "/Applications/renpy-8.3.4-sdk/renpy/python.py", line 1209, in py_eval
    return py_eval_bytecode(code, globals, locals)
  File "/Applications/renpy-8.3.4-sdk/renpy/python.py", line 1202, in py_eval_bytecode
    return eval(bytecode, globals, locals)
  File "game/mainTrail.rpy", line 3, in <module>
    if talked_to_angels == true:
NameError: name 'true' is not defined

macOS-15.3.1-arm64-arm-64bit arm64
Ren'Py 8.3.4.24120703
IndividualProject 1.0
Mon Mar 10 16:11:23 2025
